Workbook

Sheet Master_Properties
A1: ID | B1: Name | C1: Developer | D1: Location | E1: Unit Type | F1: Community Type | G1: Start Price (AED) | H1: Price per Sqm (AED) | I1: Service Charge | J1: Payment Plan | K1: Launch Date | L1: Annual Yield % | M1: Cap Appr % | N1: Total Return % | O1: Nearest Schools | P1: Nearest Hospitals | Q1: Nearest Malls | R1: Main Access Roads | S1: Mins to DT | T1: Mins to Marina | U1: Mins to DXB | V1: Mins to DWC | W1: Duplicate_Count_From_Merge | X1: Helper_Start_Price_Min_AED | Y1: Helper_Start_Price_Max_AED | Z1: Helper_Annual_Yield_Low_Pct | AA1: Helper_Annual_Yield_High_Pct | AB1: Helper_Cap_App_Low_Pct | AC1: Helper_Cap_App_High_Pct | AD1: Helper_Total_Return_Low_Pct | AE1: Helper_Total_Return_High_Pct | AF1: Helper_Launch_Year | AG1: Helper_Launch_Quarter | AH1: Helper_Asset_Class | AI1: Helper_Area_Segment | AJ1: Helper_Developer_Tier | AK1: Market_Condition | AL1: Conditions_Notes | AM1: Helper_Cap_App_Mid_Pct | AN1: Helper_Annual_Yield_Mid_Pct | AO1: Helper_Current_Realization_Factor | AP1: Helper_Current_Prime_Premium_Pct | AQ1: Helper_Current_Asset_Adjustment_Pct | AR1: Helper_Current_Supply_Adjustment_Pct | AS1: Helper_Forecast_Segment_Base_Pct | AT1: Helper_Forecast_Developer_Adjustment_Pct | AU1: Helper_Forecast_Yield_Adjustment_Pct | AV1: Helper_Forecast_Risk_Adjustment_Pct | AW1: Current_Adjustment_Rate | AX1: Forecast_12M_Base_Pct | AY1: Current_Value_Low_AED | AZ1: Current_Value_Base_AED | BA1: Current_Value_High_AED | BB1: Forecast_12M_Low_AED | BC1: Forecast_12M_Base_AED | BD1: Forecast_12M_High_AED | BE1: Forecast_24M_Base_AED | BF1: Forecast_Method | BG1: Enrichment_Refresh_Date | BH1: Source_Summary | BI1: Added_Project_Source_URL | BJ1: Added_Project_Status | BK1: Added_On
A2: 1 | B2: Grand Polo Club & Resort | C2: Emaar Properties | D2: Near The Oasis/DIP | E2: Villas & Townhouses | F2: Gated / Golf / Equine | G2: 3.6M (TH) / 5.7M (Villa) | H2: 1400-1600 | I2: TBA | J2: 80/20 | K2: Q1 2025 | L2: 5.5-6.5 | M2: 8-12 | N2: 13.5-18.5 | O2: Victory Heights / South View | P2: NMC Royal DIP | Q2: Damac Mall / First Ave | R2: Yalayis St / E611 | S2: 25 | T2: 20 | U2: 30 | V2: 18 | W2: 2 | X2: 3600000 | Y2: 5700000 | Z2: 5.5 | AA2: 6.5 | AB2: 8 | AC2: 12 | AD2: 13.5 | AE2: 18.5 | AF2: 2025 | AG2: 1 | AH2: Villa/Townhouse | AI2: FamilyVilla | AJ2: TopTier | AK2: Family-villa resilient | AL2: Villa/townhouse demand remains relatively firmer, though growth should be slower than the post-2020 surge. | AM2: 10 | AN2: 6 | AO2: 0.4 | AP2: 0 | AQ2: 0.015 | AR2: 0 | AS2: 0.025 | AT2: 0.005 | AU2: 0 | AV2: -0.005 | AW2: =IF(X2="","",(AM2/100*AO2)+AP2+AQ2+AR2) | AX2: =IF(X2="","",AS2+AT2+AU2+AV2) | AY2: =IF(AZ2="","",ROUND(AZ2*(1+Assumptions!$B$10),0)) | AZ2: =IF(X2="","",ROUND(X2*(1+AW2),0)) | BA2: =IF(AZ2="","",ROUND(AZ2*(1+Assumptions!$B$11),0)) | BB2: =IF(AZ2="","",ROUND(AZ2*(1+AX2+Assumptions!$B$10),0)) | BC2: =IF(AZ2="","",ROUND(AZ2*(1+AX2),0)) | BD2: =IF(AZ2="","",ROUND(AZ2*(1+AX2+Assumptions!$B$11),0)) | BE2: =IF(AZ2="","",ROUND(AZ2*(1+AX2)*(1+AX2),0)) | BF2: Rules-based enrichment using launch-price anchor, cap-app realization, and 2026 segment conditions. | BG2: 2026-03-17 | BH2: DLD / Digital Dubai / CBUAE / Savills / Knight Frank-Moody’s / Reuters
A3: 2 | B3: Equiterra (Phases 1 & 2) | C3: Emaar Properties | D3: Grand Polo Club | E3: Townhouses | F3: Gated Community | G3: 3.6M | H3: 1450 | I3: TBA | J3: 80/20 | K3: Q1 2025 | L3: 5.5-6.0 | M3: 8-12 | N3: 13.5-18.0 | O3: Victory Heights / South View | P3: NMC Royal DIP | Q3: Damac Mall / First Ave | R3: Yalayis St / E611 | S3: 25 | T3: 20 | U3: 30 | V3: 18 | W3: 2 | X3: 3600000 | Y3: 3600000 | Z3: 5.5 | AA3: 6 | AB3: 8 | AC3: 12 | AD3: 13.5 | AE3: 18 | AF3: 2025 | AG3: 1 | AH3: Townhouse | AI3: FamilyVilla | AJ3: TopTier | AK3: Family-villa resilient | AL3: Villa/townhouse demand remains relatively firmer, though growth should be slower than the post-2020 surge. | AM3: 10 | AN3: 5.75 | AO3: 0.4 | AP3: 0 | AQ3: 0.015 | AR3: 0 | AS3: 0.025 | AT3: 0.005 | AU3: 0 | AV3: -0.005 | AW3: =IF(X3="","",(AM3/100*AO3)+AP3+AQ3+AR3) | AX3: =IF(X3="","",AS3+AT3+AU3+AV3) | AY3: =IF(AZ3="","",ROUND(AZ3*(1+Assumptions!$B$10),0)) | AZ3: =IF(X3="","",ROUND(X3*(1+AW3),0)) | BA3: =IF(AZ3="","",ROUND(AZ3*(1+Assumptions!$B$11),0)) | BB3: =IF(AZ3="","",ROUND(AZ3*(1+AX3+Assumptions!$B$10),0)) | BC3: =IF(AZ3="","",ROUND(AZ3*(1+AX3),0)) | BD3: =IF(AZ3="","",ROUND(AZ3*(1+AX3+Assumptions!$B$11),0)) | BE3: =IF(AZ3="","",ROUND(AZ3*(1+AX3)*(1+AX3),0)) | BF3: Rules-based enrichment using launch-price anchor, cap-app realization, and 2026 segment conditions. | BG3: 2026-03-17 | BH3: DLD / Digital Dubai / CBUAE / Savills / Knight Frank-Moody’s / Reuters
A4: 3 | B4: Equestra | C4: Emaar Properties | D4: Grand Polo Club | E4: Townhouses | F4: Gated Community | G4: 3.7M | H4: 1450 | I4: TBA | J4: 80/20 | K4: Q1 2025 | L4: 5.5-6.0 | M4: 8-12 | N4: 13.5-18.0 | O4: Victory Heights / South View | P4: NMC Royal DIP | Q4: Damac Mall / First Ave | R4: Yalayis St / E611 | S4: 25 | T4: 20 | U4: 30 | V4: 18 | W4: 2 | X4: 3700000 | Y4: 3700000 | Z4: 5.5 | AA4: 6 | AB4: 8 | AC4: 12 | AD4: 13.5 | AE4: 18 | AF4: 2025 | AG4: 1 | AH4: Townhouse | AI4: FamilyVilla | AJ4: TopTier | AK4: Family-villa resilient | AL4: Villa/townhouse demand remains relatively firmer, though growth should be slower than the post-2020 surge. | AM4: 10 | AN4: 5.75 | AO4: 0.4 | AP4: 0 | AQ4: 0.015 | AR4: 0 | AS4: 0.025 | AT4: 0.005 | AU4: 0 | AV4: -0.005 | AW4: =IF(X4="","",(AM4/100*AO4)+AP4+AQ4+AR4) | AX4: =IF(X4="","",AS4+AT4+AU4+AV4) | AY4: =IF(AZ4="","",ROUND(AZ4*(1+Assumptions!$B$10),0)) | AZ4: =IF(X4="","",ROUND(X4*(1+AW4),0)) | BA4: =IF(AZ4="","",ROUND(AZ4*(1+Assumptions!$B$11),0)) | BB4: =IF(AZ4="","",ROUND(AZ4*(1+AX4+Assumptions!$B$10),0)) | BC4: =IF(AZ4="","",ROUND(AZ4*(1+AX4),0)) | BD4: =IF(AZ4="","",ROUND(AZ4*(1+AX4+Assumptions!$B$11),0)) | BE4: =IF(AZ4="","",ROUND(AZ4*(1+AX4)*(1+AX4),0)) | BF4: Rules-based enrichment using launch-price anchor, cap-app realization, and 2026 segment conditions. | BG4: 2026-03-17 | BH4: DLD / Digital Dubai / CBUAE / Savills / Knight Frank-Moody’s / Reuters
A5: 4 | B5: Chevalia Estate 2 | C5: Emaar Properties | D5: Grand Polo Club | E5: Villas (Large) | F5: Gated Community | G5: 7.9M | H5: 1600 | I5: TBA | J5: 80/20 | K5: Q1 2025 | L5: 4.5-5.5 | M5: 8-12 | N5: 12.5-17.5 | O5: Victory Heights / South View | P5: NMC Royal DIP | Q5: Damac Mall / First Ave | R5: Yalayis St / E611 | S5: 25 | T5: 20 | U5: 30 | V5: 18 | W5: 2 | X5: 7900000 | Y5: 7900000 | Z5: 4.5 | AA5: 5.5 | AB5: 8 | AC5: 12 | AD5: 12.5 | AE5: 17.5 | AF5: 2025 | AG5: 1 | AH5: Villa | AI5: FamilyVilla | AJ5: TopTier | AK5: Family-villa resilient | AL5: Villa/townhouse demand remains relatively firmer, though growth should be slower than the post-2020 surge. | AM5: 10 | AN5: 5 | AO5: 0.4 | AP5: 0 | AQ5: 0.015 | AR5: 0 | AS5: 0.025 | AT5: 0.005 | AU5: 0 | AV5: -0.005 | AW5: =IF(X5="","",(AM5/100*AO5)+AP5+AQ5+AR5) | AX5: =IF(X5="","",AS5+AT5+AU5+AV5) | AY5: =IF(AZ5="","",ROUND(AZ5*(1+Assumptions!$B$10),0)) | AZ5: =IF(X5="","",ROUND(X5*(1+AW5),0)) | BA5: =IF(AZ5="","",ROUND(AZ5*(1+Assumptions!$B$11),0)) | BB5: =IF(AZ5="","",ROUND(AZ5*(1+AX5+Assumptions!$B$10),0)) | BC5: =IF(AZ5="","",ROUND(AZ5*(1+AX5),0)) | BD5: =IF(AZ5="","",ROUND(AZ5*(1+AX5+Assumptions!$B$11),0)) | BE5: =IF(AZ5="","",ROUND(AZ5*(1+AX5)*(1+AX5),0)) | BF5: Rules-based enrichment using launch-price anchor, cap-app realization, and 2026 segment conditions. | BG5: 2026-03-17 | BH5: DLD / Digital Dubai / CBUAE / Savills / Knight Frank-Moody’s / Reuters
A6: 5 | B6: Selvara (Phases 3 & 4) | C6: Emaar Properties | D6: Grand Polo Club | E6: Villas | F6: Gated Community | G6: 6.2M | H6: 1550 | I6: TBA | J6: 80/20 | K6: Q1 2025 | L6: 5.0-5.5 | M6: 8-12 | N6: 13.0-17.5 | O6: Victory Heights / South View | P6: NMC Royal DIP | Q6: Damac Mall / First Ave | R6: Yalayis St / E611 | S6: 25 | T6: 20 | U6: 30 | V6: 18 | W6: 2 | X6: 6200000 | Y6: 6200000 | Z6: 5 | AA6: 5.5 | AB6: 8 | AC6: 12 | AD6: 13 | AE6: 17.5 | AF6: 2025 | AG6: 1 | AH6: Villa | AI6: FamilyVilla | AJ6: TopTier | AK6: Family-villa resilient | AL6: Villa/townhouse demand remains relatively firmer, though growth should be slower than the post-2020 surge. | AM6: 10 | AN6: 5.25 | AO6: 0.4 | AP6: 0 | AQ6: 0.015 | AR6: 0 | AS6: 0.025 | AT6: 0.005 | AU6: 0 | AV6: -0.005 | AW6: =IF(X6="","",(AM6/100*AO6)+AP6+AQ6+AR6) | AX6: =IF(X6="","",AS6+AT6+AU6+AV6) | AY6: =IF(AZ6="","",ROUND(AZ6*(1+Assumptions!$B$10),0)) | AZ6: =IF(X6="","",ROUND(X6*(1+AW6),0)) | BA6: =IF(AZ6="","",ROUND(AZ6*(1+Assumptions!$B$11),0)) | BB6: =IF(AZ6="","",ROUND(AZ6*(1+AX6+Assumptions!$B$10),0)) | BC6: =IF(AZ6="","",ROUND(AZ6*(1+AX6),0)) | BD6: =IF(AZ6="","",ROUND(AZ6*(1+AX6+Assumptions!$B$11),0)) | BE6: =IF(AZ6="","",ROUND(AZ6*(1+AX6)*(1+AX6),0)) | BF6: Rules-based enrichment using launch-price anchor, cap-app realization, and 2026 segment conditions. | BG6: 2026-03-17 | BH6: DLD / Digital Dubai / CBUAE / Savills / Knight Frank-Moody’s / Reuters
A7: 6 | B7: Rashid Yachts & Marina | C7: Emaar Properties | D7: Mina Rashid | E7: Mixed | F7: Waterfront / Marina | I7: 25-30 | J7: Varies | K7: 2023-2025 | L7: 5.5-6.5 | M7: 10-15 | N7: 15.5-21.5 | O7: New Academy School | P7: Aster Hospital Mankhool | Q7: Dubai Mall / City Centre | R7: Al Khaleej / E11 | S7: 15 | T7: 25 | U7: 15 | V7: 45 | W7: 2 | Z7: 5.5 | AA7: 6.5 | AB7: 10 | AC7: 15 | AD7: 15.5 | AE7: 21.5 | AF7: 2023 | AH7: Mixed/Other | AI7: MainstreamSelective | AJ7: TopTier | AK7: Balanced / selective | AL7: Market remains active but increasingly differentiated by developer, micro-location, livability, and pricing discipline. | AM7: 12.5 | AN7: 6 | AO7: 0.55 | AP7: 0 | AQ7: 0 | AR7: 0 | AS7: 0.01 | AT7: 0.005 | AU7: 0 | AV7: -0.005 | AW7: =IF(X7="","",(AM7/100*AO7)+AP7+AQ7+AR7) | AX7: =IF(X7="","",AS7+AT7+AU7+AV7) | AY7: =IF(AZ7="","",ROUND(AZ7*(1+Assumptions!$B$10),0)) | AZ7: =IF(X7="","",ROUND(X7*(1+AW7),0)) | BA7: =IF(AZ7="","",ROUND(AZ7*(1+Assumptions!$B$11),0)) | BB7: =IF(AZ7="","",ROUND(AZ7*(1+AX7+Assumptions!$B$10),0)) | BC7: =IF(AZ7="","",ROUND(AZ7*(1+AX7),0)) | BD7: =IF(AZ7="","",ROUND(AZ7*(1+AX7+Assumptions!$B$11),0)) | BE7: =IF(AZ7="","",ROUND(AZ7*(1+AX7)*(1+AX7),0)) | BF7: Rules-based enrichment using launch-price anchor, cap-app realization, and 2026 segment conditions. | BG7: 2026-03-17 | BH7: DLD / Digital Dubai / CBUAE / Savills / Knight Frank-Moody’s / Reuters
A8: 7 | B8: Aurea | C8: Emaar Properties | D8: Rashid Yachts & Marina | E8: Apartments | F8: Waterfront | G8: 1.8M | H8: 2200 | I8: 25 | J8: 80/20 | K8: 2024 | L8: 5.5-6.0 | M8: 10-12 | N8: 15.5-18.0 | O8: New Academy School | P8: Aster Hospital Mankhool | Q8: Dubai Mall / City Centre | R8: Al Khaleej / E11 | S8: 15 | T8: 25 | U8: 15 | V8: 45 | W8: 2 | X8: 1800000 | Y8: 1800000 | Z8: 5.5 | AA8: 6 | AB8: 10 | AC8: 12 | AD8: 15.5 | AE8: 18 | AF8: 2024 | AH8: Apartment | AI8: MainstreamSelective | AJ8: TopTier | AK8: Balanced / selective | AL8: Market remains active but increasingly differentiated by developer, micro-location, livability, and pricing discipline. | AM8: 11 | AN8: 5.75 | AO8: 0.55 | AP8: 0 | AQ8: 0 | AR8: 0 | AS8: 0.01 | AT8: 0.005 | AU8: 0 | AV8: -0.005 | AW8: =IF(X8="","",(AM8/100*AO8)+AP8+AQ8+AR8) | AX8: =IF(X8="","",AS8+AT8+AU8+AV8) | AY8: =IF(AZ8="","",ROUND(AZ8*(1+Assumptions!$B$10),0)) | AZ8: =IF(X8="","",ROUND(X8*(1+AW8),0)) | BA8: =IF(AZ8="","",ROUND(AZ8*(1+Assumptions!$B$11),0)) | BB8: =IF(AZ8="","",ROUND(AZ8*(1+AX8+Assumptions!$B$10),0)) | BC8: =IF(AZ8="","",ROUND(AZ8*(1+AX8),0)) | BD8: =IF(AZ8="","",ROUND(AZ8*(1+AX8+Assumptions!$B$11),0)) | BE8: =IF(AZ8="","",ROUND(AZ8*(1+AX8)*(1+AX8),0)) | BF8: Rules-based enrichment using launch-price anchor, cap-app realization, and 2026 segment conditions. | BG8: 2026-03-17 | BH8: DLD / Digital Dubai / CBUAE / Savills / Knight Frank-Moody’s / Reuters
A9: 8 | B9: Pier Point | C9: Emaar Properties | D9: Rashid Yachts & Marina | E9: Apartments | F9: Waterfront | G9: 2.1M | H9: 2300 | I9: 25 | J9: 80/20 | K9: 2024 | L9: 5.5-6.0 | M9: 10-12 | N9: 15.5-18.0 | O9: New Academy School | P9: Aster Hospital Mankhool | Q9: Dubai Mall / City Centre | R9: Al Khaleej / E11 | S9: 15 | T9: 25 | U9: 15 | V9: 45 | W9: 2 | X9: 2100000 | Y9: 2100000 | Z9: 5.5 | AA9: 6 | AB9: 10 | AC9: 12 | AD9: 15.5 | AE9: 18 | AF9: 2024 | AH9: Apartment | AI9: MainstreamSelective | AJ9: TopTier | AK9: Balanced / selective | AL9: Market remains active but increasingly differentiated by developer, micro-location, livability, and pricing discipline. | AM9: 11 | AN9: 5.75 | AO9: 0.55 | AP9: 0 | AQ9: 0 | AR9: 0 | AS9: 0.01 | AT9: 0.005 | AU9: 0 | AV9: -0.005 | AW9: =IF(X9="","",(AM9/100*AO9)+AP9+AQ9+AR9) | AX9: =IF(X9="","",AS9+AT9+AU9+AV9) | AY9: =IF(AZ9="","",ROUND(AZ9*(1+Assumptions!$B$10),0)) | AZ9: =IF(X9="","",ROUND(X9*(1+AW9),0)) | BA9: =IF(AZ9="","",ROUND(AZ9*(1+Assumptions!$B$11),0)) | BB9: =IF(AZ9="","",ROUND(AZ9*(1+AX9+Assumptions!$B$10),0)) | BC9: =IF(AZ9="","",ROUND(AZ9*(1+AX9),0)) | BD9: =IF(AZ9="","",ROUND(AZ9*(1+AX9+Assumptions!$B$11),0)) | BE9: =IF(AZ9="","",ROUND(AZ9*(1+AX9)*(1+AX9),0)) | BF9: Rules-based enrichment using launch-price anchor, cap-app realization, and 2026 segment conditions. | BG9: 2026-03-17 | BH9: DLD / Digital Dubai / CBUAE / Savills / Knight Frank-Moody’s / Reuters
A10: 9 | B10: Marina Cove | C10: Emaar Properties | D10: Rashid Yachts & Marina | E10: Apartments | F10: Waterfront | G10: 1.9M | H10: 2250 | I10: 25 | J10: 80/20 | K10: 2024 | L10: 5.5-6.0 | M10: 10-12 | N10: 15.5-18.0 | O10: New Academy School | P10: Aster Hospital Mankhool | Q10: Dubai Mall / City Centre | R10: Al Khaleej / E11 | S10: 15 | T10: 25 | U10: 15 | V10: 45 | W10: 2 | X10: 1900000 | Y10: 1900000 | Z10: 5.5 | AA10: 6 | AB10: 10 | AC10: 12 | AD10: 15.5 | AE10: 18 | AF10: 2024 | AH10: Apartment | AI10: MainstreamSelective | AJ10: TopTier | AK10: Balanced / selective | AL10: Market remains active but increasingly differentiated by developer, micro-location, livability, and pricing discipline. | AM10: 11 | AN10: 5.75 | AO10: 0.55 | AP10: 0 | AQ10: 0 | AR10: 0 | AS10: 0.01 | AT10: 0.005 | AU10: 0 | AV10: -0.005 | AW10: =IF(X10="","",(AM10/100*AO10)+AP10+AQ10+AR10) | AX10: =IF(X10="","",AS10+AT10+AU10+AV10) | AY10: =IF(AZ10="","",ROUND(AZ10*(1+Assumptions!$B$10),0)) | AZ10: =IF(X10="","",ROUND(X10*(1+AW10),0)) | BA10: =IF(AZ10="","",ROUND(AZ10*(1+Assumptions!$B$11),0)) | BB10: =IF(AZ10="","",ROUND(AZ10*(1+AX10+Assumptions!$B$10),0)) | BC10: =IF(AZ10="","",ROUND(AZ10*(1+AX10),0)) | BD10: =IF(AZ10="","",ROUND(AZ10*(1+AX10+Assumptions!$B$11),0)) | BE10: =IF(AZ10="","",ROUND(AZ10*(1+AX10)*(1+AX10),0)) | BF10: Rules-based enrichment using launch-price anchor, cap-app realization, and 2026 segment conditions. | BG10: 2026-03-17 | BH10: DLD / Digital Dubai / CBUAE / Savills / Knight Frank-Moody’s / Reuters
A11: 10 | B11: Sera 2 | C11: Emaar Properties | D11: Rashid Yachts & Marina | E11: Apartments | F11: Waterfront | G11: 1.7M | H11: 2100 | I11: 25 | J11: 80/20 | K11: 2024 | L11: 6.0-6.5 | M11: 10-12 | N11: 16.0-18.5 | O11: New Academy School | P11: Aster Hospital Mankhool | Q11: Dubai Mall / City Centre | R11: Al Khaleej / E11 | S11: 15 | T11: 25 | U11: 15 | V11: 45 | W11: 2 | X11: 1700000 | Y11: 1700000 | Z11: 6 | AA11: 6.5 | AB11: 10 | AC11: 12 | AD11: 16 | AE11: 18.5 | AF11: 2024 | AH11: Apartment | AI11: MainstreamSelective | AJ11: TopTier | AK11: Balanced / selective | AL11: Market remains active but increasingly differentiated by developer, micro-location, livability, and pricing discipline. | AM11: 11 | AN11: 6.25 | AO11: 0.55 | AP11: 0 | AQ11: 0 | AR11: 0 | AS11: 0.01 | AT11: 0.005 | AU11: 0.0025 | AV11: -0.005 | AW11: =IF(X11="","",(AM11/100*AO11)+AP11+AQ11+AR11) | AX11: =IF(X11="","",AS11+AT11+AU11+AV11) | AY11: =IF(AZ11="","",ROUND(AZ11*(1+Assumptions!$B$10),0)) | AZ11: =IF(X11="","",ROUND(X11*(1+AW11),0)) | BA11: =IF(AZ11="","",ROUND(AZ11*(1+Assumptions!$B$11),0)) | BB11: =IF(AZ11="","",ROUND(AZ11*(1+AX11+Assumptions!$B$10),0)) | BC11: =IF(AZ11="","",ROUND(AZ11*(1+AX11),0)) | BD11: =IF(AZ11="","",ROUND(AZ11*(1+AX11+Assumptions!$B$11),0)) | BE11: =IF(AZ11="","",ROUND(AZ11*(1+AX11)*(1+AX11),0)) | BF11: Rules-based enrichment using launch-price anchor, cap-app realization, and 2026 segment conditions. | BG11: 2026-03-17 | BH11: DLD / Digital Dubai / CBUAE / Savills / Knight Frank-Moody’s / Reuters
A12: 11 | B12: Ocean Cove | C12: Emaar Properties | D12: Rashid Yachts & Marina | E12: Apartments | F12: Waterfront | G12: 1.8M | H12: 2200 | I12: 25 | J12: 80/20 | K12: 2024 | L12: 5.5-6.0 | M12: 10-12 | N12: 15.5-18.0 | O12: New Academy School | P12: Aster Hospital Mankhool | Q12: Dubai Mall / City Centre | R12: Al Khaleej / E11 | S12: 15 | T12: 25 | U12: 15 | V12: 45 | W12: 2 | X12: 1800000 | Y12: 1800000 | Z12: 5.5 | AA12: 6 | AB12: 10 | AC12: 12 | AD12: 15.5 | AE12: 18 | AF12: 2024 | AH12: Apartment | AI12: MainstreamSelective | AJ12: TopTier | AK12: Balanced / selective | AL12: Market remains active but increasingly differentiated by developer, micro-location, livability, and pricing discipline. | AM12: 11 | AN12: 5.75 | AO12: 0.55 | AP12: 0 | AQ12: 0 | AR12: 0 | AS12: 0.01 | AT12: 0.005 | AU12: 0 | AV12: -0.005 | AW12: =IF(X12="","",(AM12/100*AO12)+AP12+AQ12+AR12) | AX12: =IF(X12="","",AS12+AT12+AU12+AV12) | AY12: =IF(AZ12="","",ROUND(AZ12*(1+Assumptions!$B$10),0)) | AZ12: =IF(X12="","",ROUND(X12*(1+AW12),0)) | BA12: =IF(AZ12="","",ROUND(AZ12*(1+Assumptions!$B$11),0)) | BB12: =IF(AZ12="","",ROUND(AZ12*(1+AX12+Assumptions!$B$10),0)) | BC12: =IF(AZ12="","",ROUND(AZ12*(1+AX12),0)) | BD12: =IF(AZ12="","",ROUND(AZ12*(1+AX12+Assumptions!$B$11),0)) | BE12: =IF(AZ12="","",ROUND(AZ12*(1+AX12)*(1+AX12),0)) | BF12: Rules-based enrichment using launch-price anchor, cap-app realization, and 2026 segment conditions. | BG12: 2026-03-17 | BH12: DLD / Digital Dubai / CBUAE / Savills / Knight Frank-Moody’s / Reuters
A13: 12 | B13: Baystar | C13: Emaar Properties | D13: Rashid Yachts & Marina | E13: Apartments | F13: Waterfront | G13: 1.75M | H13: 2150 | I13: 25 | J13: 80/20 | K13: 2024 | L13: 5.5-6.0 | M13: 10-12 | N13: 15.5-18.0 | O13: New Academy School | P13: Aster Hospital Mankhool | Q13: Dubai Mall / City Centre | R13: Al Khaleej / E11 | S13: 15 | T13: 25 | U13: 15 | V13: 45 | W13: 2 | X13: 1750000 | Y13: 1750000 | Z13: 5.5 | AA13: 6 | AB13: 10 | AC13: 12 | AD13: 15.5 | AE13: 18 | AF13: 2024 | AH13: Apartment | AI13: MainstreamSelective | AJ13: TopTier | AK13: Balanced / selective | AL13: Market remains active but increasingly differentiated by developer, micro-location, livability, and pricing discipline. | AM13: 11 | AN13: 5.75 | AO13: 0.55 | AP13: 0 | AQ13: 0 | AR13: 0 | AS13: 0.01 | AT13: 0.005 | AU13: 0 | AV13: -0.005 | AW13: =IF(X13="","",(AM13/100*AO13)+AP13+AQ13+AR13) | AX13: =IF(X13="","",AS13+AT13+AU13+AV13) | AY13: =IF(AZ13="","",ROUND(AZ13*(1+Assumptions!$B$10),0)) | AZ13: =IF(X13="","",ROUND(X13*(1+AW13),0)) | BA13: =IF(AZ13="","",ROUND(AZ13*(1+Assumptions!$B$11),0)) | BB13: =IF(AZ13="","",ROUND(AZ13*(1+AX13+Assumptions!$B$10),0)) | BC13: =IF(AZ13="","",ROUND(AZ13*(1+AX13),0)) | BD13: =IF(AZ13="","",ROUND(AZ13*(1+AX13+Assumptions!$B$11),0)) | BE13: =IF(AZ13="","",ROUND(AZ13*(1+AX13)*(1+AX13),0)) | BF13: Rules-based enrichment using launch-price anchor, cap-app realization, and 2026 segment conditions. | BG13: 2026-03-17 | BH13: DLD / Digital Dubai / CBUAE / Savills / Knight Frank-Moody’s / Reuters
A14: 13 | B14: Seagate | C14: Emaar Properties | D14: Rashid Yachts & Marina | E14: Apartments | F14: Waterfront | G14: 1.6M | H14: 2000 | I14: 25 | J14: 80/20 | K14: 2023 | L14: 6.0-6.5 | M14: 8-10 | N14: 14.0-16.5 | O14: New Academy School | P14: Aster Hospital Mankhool | Q14: Dubai Mall / City Centre | R14: Al Khaleej / E11 | S14: 15 | T14: 25 | U14: 15 | V14: 45 | W14: 2 | X14: 1600000 | Y14: 1600000 | Z14: 6 | AA14: 6.5 | AB14: 8 | AC14: 10 | AD14: 14 | AE14: 16.5 | AF14: 2023 | AH14: Apartment | AI14: MainstreamSelective | AJ14: TopTier | AK14: Balanced / selective | AL14: Market remains active but increasingly differentiated by developer, micro-location, livability, and pricing discipline. | AM14: 9 | AN14: 6.25 | AO14: 0.55 | AP14: 0 | AQ14: 0 | AR14: 0 | AS14: 0.01 | AT14: 0.005 | AU14: 0.0025 | AV14: -0.005 | AW14: =IF(X14="","",(AM14/100*AO14)+AP14+AQ14+AR14) | AX14: =IF(X14="","",AS14+AT14+AU14+AV14) | AY14: =IF(AZ14="","",ROUND(AZ14*(1+Assumptions!$B$10),0)) | AZ14: =IF(X14="","",ROUND(X14*(1+AW14),0)) | BA14: =IF(AZ14="","",ROUND(AZ14*(1+Assumptions!$B$11),0)) | BB14: =IF(AZ14="","",ROUND(AZ14*(1+AX14+Assumptions!$B$10),0)) | BC14: =IF(AZ14="","",ROUND(AZ14*(1+AX14),0)) | BD14: =IF(AZ14="","",ROUND(AZ14*(1+AX14+Assumptions!$B$11),0)) | BE14: =IF(AZ14="","",ROUND(AZ14*(1+AX14)*(1+AX14),0)) | BF14: Rules-based enrichment using launch-price anchor, cap-app realization, and 2026 segment conditions. | BG14: 2026-03-17 | BH14: DLD / Digital Dubai / CBUAE / Savills / Knight Frank-Moody’s / Reuters
A15: 14 | B15: Clearpoint | C15: Emaar Properties | D15: Rashid Yachts & Marina | E15: Apartments | F15: Waterfront | G15: 1.6M | H15: 2000 | I15: 25 | J15: 80/20 | K15: 2023 | L15: 6.0-6.5 | M15: 8-10 | N15: 14.0-16.5 | O15: New Academy School | P15: Aster Hospital Mankhool | Q15: Dubai Mall / City Centre | R15: Al Khaleej / E11 | S15: 15 | T15: 25 | U15: 15 | V15: 45 | W15: 2 | X15: 1600000 | Y15: 1600000 | Z15: 6 | AA15: 6.5 | AB15: 8 | AC15: 10 | AD15: 14 | AE15: 16.5 | AF15: 2023 | AH15: Apartment | AI15: MainstreamSelective | AJ15: TopTier | AK15: Balanced / selective | AL15: Market remains active but increasingly differentiated by developer, micro-location, livability, and pricing discipline. | AM15: 9 | AN15: 6.25 | AO15: 0.55 | AP15: 0 | AQ15: 0 | AR15: 0 | AS15: 0.01 | AT15: 0.005 | AU15: 0.0025 | AV15: -0.005 | AW15: =IF(X15="","",(AM15/100*AO15)+AP15+AQ15+AR15) | AX15: =IF(X15="","",AS15+AT15+AU15+AV15) | AY15: =IF(AZ15="","",ROUND(AZ15*(1+Assumptions!$B$10),0)) | AZ15: =IF(X15="","",ROUND(X15*(1+AW15),0)) | BA15: =IF(AZ15="","",ROUND(AZ15*(1+Assumptions!$B$11),0)) | BB15: =IF(AZ15="","",ROUND(AZ15*(1+AX15+Assumptions!$B$10),0)) | BC15: =IF(AZ15="","",ROUND(AZ15*(1+AX15),0)) | BD15: =IF(AZ15="","",ROUND(AZ15*(1+AX15+Assumptions!$B$11),0)) | BE15: =IF(AZ15="","",ROUND(AZ15*(1+AX15)*(1+AX15),0)) | BF15: Rules-based enrichment using launch-price anchor, cap-app realization, and 2026 segment conditions. | BG15: 2026-03-17 | BH15: DLD / Digital Dubai / CBUAE / Savills / Knight Frank-Moody’s / Reuters
A16: 15 | B16: Sunridge | C16: Emaar Properties | D16: Rashid Yachts & Marina | E16: Apartments | F16: Waterfront | G16: 1.55M | H16: 1950 | I16: 25 | J16: 80/20 | K16: 2023 | L16: 6.0-6.5 | M16: 8-10 | N16: 14.0-16.5 | O16: New Academy School | P16: Aster Hospital Mankhool | Q16: Dubai Mall / City Centre | R16: Al Khaleej / E11 | S16: 15 | T16: 25 | U16: 15 | V16: 45 | W16: 2 | X16: 1550000 | Y16: 1550000 | Z16: 6 | AA16: 6.5 | AB16: 8 | AC16: 10 | AD16: 14 | AE16: 16.5 | AF16: 2023 | AH16: Apartment | AI16: MainstreamSelective | AJ16: TopTier | AK16: Balanced / selective | AL16: Market remains active but increasingly differentiated by developer, micro-location, livability, and pricing discipline. | AM16: 9 | AN16: 6.25 | AO16: 0.55 | AP16: 0 | AQ16: 0 | AR16: 0 | AS16: 0.01 | AT16: 0.005 | AU16: 0.0025 | AV16: -0.005 | AW16: =IF(X16="","",(AM16/100*AO16)+AP16+AQ16+AR16) | AX16: =IF(X16="","",AS16+AT16+AU16+AV16) | AY16: =IF(AZ16="","",ROUND(AZ16*(1+Assumptions!$B$10),0)) | AZ16: =IF(X16="","",ROUND(X16*(1+AW16),0)) | BA16: =IF(AZ16="","",ROUND(AZ16*(1+Assumptions!$B$11),0)) | BB16: =IF(AZ16="","",ROUND(AZ16*(1+AX16+Assumptions!$B$10),0)) | BC16: =IF(AZ16="","",ROUND(AZ16*(1+AX16),0)) | BD16: =IF(AZ16="","",ROUND(AZ16*(1+AX16+Assumptions!$B$11),0)) | BE16: =IF(AZ16="","",ROUND(AZ16*(1+AX16)*(1+AX16),0)) | BF16: Rules-based enrichment using launch-price anchor, cap-app realization, and 2026 segment conditions. | BG16: 2026-03-17 | BH16: DLD / Digital Dubai / CBUAE / Savills / Knight Frank-Moody’s / Reuters
A17: 16 | B17: Dubai Creek Harbour | C17: Emaar Properties | D17: The Creek | E17: Mixed | F17: Waterfront / City | I17: 25-30 | J17: Varies | K17: Ongoing | L17: 5.5-6.5 | M17: 9-12 | N17: 14.5-18.5 | O17: Swiss Intl School | P17: American Hospital | Q17: Dubai Festival City | R17: Ras Al Khor / E44 | S17: 12 | T17: 25 | U17: 10 | V17: 40 | W17: 2 | Z17: 5.5 | AA17: 6.5 | AB17: 9 | AC17: 12 | AD17: 14.5 | AE17: 18.5 | AH17: Mixed/Other | AI17: MainstreamSelective | AJ17: TopTier | AK17: Balanced / selective | AL17: Market remains active but increasingly differentiated by developer, micro-location, livability, and pricing discipline. | AM17: 10.5 | AN17: 6 | AO17: 0.25 | AP17: 0 | AQ17: 0 | AR17: 0 | AS17: 0.01 | AT17: 0.005 | AU17: 0 | AV17: -0.005 | AW17: =IF(X17="","",(AM17/100*AO17)+AP17+AQ17+AR17) | AX17: =IF(X17="","",AS17+AT17+AU17+AV17) | AY17: =IF(AZ17="","",ROUND(AZ17*(1+Assumptions!$B$10),0)) | AZ17: =IF(X17="","",ROUND(X17*(1+AW17),0)) | BA17: =IF(AZ17="","",ROUND(AZ17*(1+Assumptions!$B$11),0)) | BB17: =IF(AZ17="","",ROUND(AZ17*(1+AX17+Assumptions!$B$10),0)) | BC17: =IF(AZ17="","",ROUND(AZ17*(1+AX17),0)) | BD17: =IF(AZ17="","",ROUND(AZ17*(1+AX17+Assumptions!$B$11),0)) | BE17: =IF(AZ17="","",ROUND(AZ17*(1+AX17)*(1+AX17),0)) | BF17: Rules-based enrichment using launch-price anchor, cap-app realization, and 2026 segment conditions. | BG17: 2026-03-17 | BH17: DLD / Digital Dubai / CBUAE / Savills / Knight Frank-Moody’s / Reuters
A18: 17 | B18: Valo | C18: Emaar Properties | D18: Dubai Creek Harbour | E18: Apartments | F18: Waterfront / Metro | G18: 1.9M | H18: 2300 | I18: 25 | J18: 80/20 | K18: 2024 | L18: 5.5-6.0 | M18: 9-12 | N18: 14.5-18.0 | O18: Swiss Intl School | P18: American Hospital | Q18: Dubai Festival City | R18: Ras Al Khor / E44 | S18: 12 | T18: 25 | U18: 10 | V18: 40 | W18: 2 | X18: 1900000 | Y18: 1900000 | Z18: 5.5 | AA18: 6 | AB18: 9 | AC18: 12 | AD18: 14.5 | AE18: 18 | AF18: 2024 | AH18: Apartment | AI18: Prime | AJ18: TopTier | AK18: Prime resilient / selective | AL18: Better support from quality, branding, and scarcer prime stock; still entry-price sensitive. | AM18: 10.5 | AN18: 5.75 | AO18: 0.55 | AP18: 0.02 | AQ18: 0 | AR18: 0 | AS18: 0.03 | AT18: 0.005 | AU18: 0 | AV18: -0.005 | AW18: =IF(X18="","",(AM18/100*AO18)+AP18+AQ18+AR18) | AX18: =IF(X18="","",AS18+AT18+AU18+AV18) | AY18: =IF(AZ18="","",ROUND(AZ18*(1+Assumptions!$B$10),0)) | AZ18: =IF(X18="","",ROUND(X18*(1+AW18),0)) | BA18: =IF(AZ18="","",ROUND(AZ18*(1+Assumptions!$B$11),0)) | BB18: =IF(AZ18="","",ROUND(AZ18*(1+AX18+Assumptions!$B$10),0)) | BC18: =IF(AZ18="","",ROUND(AZ18*(1+AX18),0)) | BD18: =IF(AZ18="","",ROUND(AZ18*(1+AX18+Assumptions!$B$11),0)) | BE18: =IF(AZ18="","",ROUND(AZ18*(1+AX18)*(1+AX18),0)) | BF18: Rules-based enrichment using launch-price anchor, cap-app realization, and 2026 segment conditions. | BG18: 2026-03-17 | BH18: DLD / Digital Dubai / CBUAE / Savills / Knight Frank-Moody’s / Reuters
A19: 18 | B19: Aeon | C19: Emaar Properties | D19: Dubai Creek Harbour | E19: Apartments | F19: Waterfront | G19: 1.8M | H19: 2200 | I19: 25 | J19: 80/20 | K19: 2024 | L19: 5.5-6.0 | M19: 9-12 | N19: 14.5-18.0 | O19: Swiss Intl School | P19: American Hospital | Q19: Dubai Festival City | R19: Ras Al Khor / E44 | S19: 12 | T19: 25 | U19: 10 | V19: 40 | W19: 2 | X19: 1800000 | Y19: 1800000 | Z19: 5.5 | AA19: 6 | AB19: 9 | AC19: 12 | AD19: 14.5 | AE19: 18 | AF19: 2024 | AH19: Apartment | AI19: Prime | AJ19: TopTier | AK19: Prime resilient / selective | AL19: Better support from quality, branding, and scarcer prime stock; still entry-price sensitive. | AM19: 10.5 | AN19: 5.75 | AO19: 0.55 | AP19: 0.02 | AQ19: 0 | AR19: 0 | AS19: 0.03 | AT19: 0.005 | AU19: 0 | AV19: -0.005 | AW19: =IF(X19="","",(AM19/100*AO19)+AP19+AQ19+AR19) | AX19: =IF(X19="","",AS19+AT19+AU19+AV19) | AY19: =IF(AZ19="","",ROUND(AZ19*(1+Assumptions!$B$10),0)) | AZ19: =IF(X19="","",ROUND(X19*(1+AW19),0)) | BA19: =IF(AZ19="","",ROUND(AZ19*(1+Assumptions!$B$11),0)) | BB19: =IF(AZ19="","",ROUND(AZ19*(1+AX19+Assumptions!$B$10),0)) | BC19: =IF(AZ19="","",ROUND(AZ19*(1+AX19),0)) | BD19: =IF(AZ19="","",ROUND(AZ19*(1+AX19+Assumptions!$B$11),0)) | BE19: =IF(AZ19="","",ROUND(AZ19*(1+AX19)*(1+AX19),0)) | BF19: Rules-based enrichment using launch-price anchor, cap-app realization, and 2026 segment conditions. | BG19: 2026-03-17 | BH19: DLD / Digital Dubai / CBUAE / Savills / Knight Frank-Moody’s / Reuters
A20: 19 | B20: Oria | C20: Emaar Properties | D20: Dubai Creek Harbour | E20: Apartments | F20: Waterfront | G20: 1.7M | H20: 2100 | I20: 25 | J20: 80/20 | K20: 2024 | L20: 6.0-6.5 | M20: 9-12 | N20: 15.0-18.5 | O20: Swiss Intl School | P20: American Hospital | Q20: Dubai Festival City | R20: Ras Al Khor / E44 | S20: 12 | T20: 25 | U20: 10 | V20: 40 | W20: 2 | X20: 1700000 | Y20: 1700000 | Z20: 6 | AA20: 6.5 | AB20: 9 | AC20: 12 | AD20: 15 | AE20: 18.5 | AF20: 2024 | AH20: Apartment | AI20: Prime | AJ20: TopTier | AK20: Prime resilient / selective | AL20: Better support from quality, branding, and scarcer prime stock; still entry-price sensitive. | AM20: 10.5 | AN20: 6.25 | AO20: 0.55 | AP20: 0.02 | AQ20: 0 | AR20: 0 | AS20: 0.03 | AT20: 0.005 | AU20: 0.0025 | AV20: -0.005 | AW20: =IF(X20="","",(AM20/100*AO20)+AP20+AQ20+AR20) | AX20: =IF(X20="","",AS20+AT20+AU20+AV20) | AY20: =IF(AZ20="","",ROUND(AZ20*(1+Assumptions!$B$10),0)) | AZ20: =IF(X20="","",ROUND(X20*(1+AW20),0)) | BA20: =IF(AZ20="","",ROUND(AZ20*(1+Assumptions!$B$11),0)) | BB20: =IF(AZ20="","",ROUND(AZ20*(1+AX20+Assumptions!$B$10),0)) | BC20: =IF(AZ20="","",ROUND(AZ20*(1+AX20),0)) | BD20: =IF(AZ20="","",ROUND(AZ20*(1+AX20+Assumptions!$B$11),0)) | BE20: =IF(AZ20="","",ROUND(AZ20*(1+AX20)*(1+AX20),0)) | BF20: Rules-based enrichment using launch-price anchor, cap-app realization, and 2026 segment conditions. | BG20: 2026-03-17 | BH20: DLD / Digital Dubai / CBUAE / Savills / Knight Frank-Moody’s / Reuters
A21: 20 | B21: Mangrove (Creek Beach) | C21: Emaar Properties | D21: Dubai Creek Harbour | E21: Apartments | F21: Beachfront | G21: 1.6M | H21: 2000 | I21: 25 | J21: 80/20 | K21: 2024 | L21: 6.0-6.5 | M21: 9-12 | N21: 15.0-18.5 | O21: Swiss Intl School | P21: American Hospital | Q21: Dubai Festival City | R21: Ras Al Khor / E44 | S21: 12 | T21: 25 | U21: 10 | V21: 40 | W21: 2 | X21: 1600000 | Y21: 1600000 | Z21: 6 | AA21: 6.5 | AB21: 9 | AC21: 12 | AD21: 15 | AE21: 18.5 | AF21: 2024 | AH21: Apartment | AI21: Prime | AJ21: TopTier | AK21: Prime resilient / selective | AL21: Better support from quality, branding, and scarcer prime stock; still entry-price sensitive. | AM21: 10.5 | AN21: 6.25 | AO21: 0.55 | AP21: 0.02 | AQ21: 0 | AR21: 0 | AS21: 0.03 | AT21: 0.005 | AU21: 0.0025 | AV21: -0.005 | AW21: =IF(X21="","",(AM21/100*AO21)+AP21+AQ21+AR21) | AX21: =IF(X21="","",AS21+AT21+AU21+AV21) | AY21: =IF(AZ21="","",ROUND(AZ21*(1+Assumptions!$B$10),0)) | AZ21: =IF(X21="","",ROUND(X21*(1+AW21),0)) | BA21: =IF(AZ21="","",ROUND(AZ21*(1+Assumptions!$B$11),0)) | BB21: =IF(AZ21="","",ROUND(AZ21*(1+AX21+Assumptions!$B$10),0)) | BC21: =IF(AZ21="","",ROUND(AZ21*(1+AX21),0)) | BD21: =IF(AZ21="","",ROUND(AZ21*(1+AX21+Assumptions!$B$11),0)) | BE21: =IF(AZ21="","",ROUND(AZ21*(1+AX21)*(1+AX21),0)) | BF21: Rules-based enrichment using launch-price anchor, cap-app realization, and 2026 segment conditions. | BG21: 2026-03-17 | BH21: DLD / Digital Dubai / CBUAE / Savills / Knight Frank-Moody’s / Reuters
A22: 21 | B22: Altan | C22: Emaar Properties | D22: Dubai Creek Harbour | E22: Apartments | F22: Waterfront | G22: 1.8M | H22: 2200 | I22: 25 | J22: 80/20 | K22: 2024 | L22: 5.5-6.0 | M22: 9-12 | N22: 14.5-18.0 | O22: Swiss Intl School | P22: American Hospital | Q22: Dubai Festival City | R22: Ras Al Khor / E44 | S22: 12 | T22: 25 | U22: 10 | V22: 40 | W22: 2 | X22: 1800000 | Y22: 1800000 | Z22: 5.5 | AA22: 6 | AB22: 9 | AC22: 12 | AD22: 14.5 | AE22: 18 | AF22: 2024 | AH22: Apartment | AI22: Prime | AJ22: TopTier | AK22: Prime resilient / selective | AL22: Better support from quality, branding, and scarcer prime stock; still entry-price sensitive. | AM22: 10.5 | AN22: 5.75 | AO22: 0.55 | AP22: 0.02 | AQ22: 0 | AR22: 0 | AS22: 0.03 | AT22: 0.005 | AU22: 0 | AV22: -0.005 | AW22: =IF(X22="","",(AM22/100*AO22)+AP22+AQ22+AR22) | AX22: =IF(X22="","",AS22+AT22+AU22+AV22) | AY22: =IF(AZ22="","",ROUND(AZ22*(1+Assumptions!$B$10),0)) | AZ22: =IF(X22="","",ROUND(X22*(1+AW22),0)) | BA22: =IF(AZ22="","",ROUND(AZ22*(1+Assumptions!$B$11),0)) | BB22: =IF(AZ22="","",ROUND(AZ22*(1+AX22+Assumptions!$B$10),0)) | BC22: =IF(AZ22="","",ROUND(AZ22*(1+AX22),0)) | BD22: =IF(AZ22="","",ROUND(AZ22*(1+AX22+Assumptions!$B$11),0)) | BE22: =IF(AZ22="","",ROUND(AZ22*(1+AX22)*(1+AX22),0)) | BF22: Rules-based enrichment using launch-price anchor, cap-app realization, and 2026 segment conditions. | BG22: 2026-03-17 | BH22: DLD / Digital Dubai / CBUAE / Savills / Knight Frank-Moody’s / Reuters
A23: 22 | B23: Silva | C23: Emaar Properties | D23: Dubai Creek Harbour | E23: Apartments | F23: Waterfront | G23: 1.85M | H23: 2250 | I23: 25 | J23: 80/20 | K23: 2024 | L23: 5.5-6.0 | M23: 9-12 | N23: 14.5-18.0 | O23: Swiss Intl School | P23: American Hospital | Q23: Dubai Festival City | R23: Ras Al Khor / E44 | S23: 12 | T23: 25 | U23: 10 | V23: 40 | W23: 2 | X23: 1850000 | Y23: 1850000 | Z23: 5.5 | AA23: 6 | AB23: 9 | AC23: 12 | AD23: 14.5 | AE23: 18 | AF23: 2024 | AH23: Apartment | AI23: Prime | AJ23: TopTier | AK23: Prime resilient / selective | AL23: Better support from quality, branding, and scarcer prime stock; still entry-price sensitive. | AM23: 10.5 | AN23: 5.75 | AO23: 0.55 | AP23: 0.02 | AQ23: 0 | AR23: 0 | AS23: 0.03 | AT23: 0.005 | AU23: 0 | AV23: -0.005 | AW23: =IF(X23="","",(AM23/100*AO23)+AP23+AQ23+AR23) | AX23: =IF(X23="","",AS23+AT23+AU23+AV23) | AY23: =IF(AZ23="","",ROUND(AZ23*(1+Assumptions!$B$10),0)) | AZ23: =IF(X23="","",ROUND(X23*(1+AW23),0)) | BA23: =IF(AZ23="","",ROUND(AZ23*(1+Assumptions!$B$11),0)) | BB23: =IF(AZ23="","",ROUND(AZ23*(1+AX23+Assumptions!$B$10),0)) | BC23: =IF(AZ23="","",ROUND(AZ23*(1+AX23),0)) | BD23: =IF(AZ23="","",ROUND(AZ23*(1+AX23+Assumptions!$B$11),0)) | BE23: =IF(AZ23="","",ROUND(AZ23*(1+AX23)*(1+AX23),0)) | BF23: Rules-based enrichment using launch-price anchor, cap-app realization, and 2026 segment conditions. | BG23: 2026-03-17 | BH23: DLD / Digital Dubai / CBUAE / Savills / Knight Frank-Moody’s / Reuters
A24: 23 | B24: Albero | C24: Emaar Properties | D24: Dubai Creek Harbour | E24: Apartments | F24: Waterfront | G24: 1.75M | H24: 2150 | I24: 25 | J24: 80/20 | K24: 2024 | L24: 5.5-6.0 | M24: 9-12 | N24: 14.5-18.0 | O24: Swiss Intl School | P24: American Hospital | Q24: Dubai Festival City | R24: Ras Al Khor / E44 | S24: 12 | T24: 25 | U24: 10 | V24: 40 | W24: 2 | X24: 1750000 | Y24: 1750000 | Z24: 5.5 | AA24: 6 | AB24: 9 | AC24: 12 | AD24: 14.5 | AE24: 18 | AF24: 2024 | AH24: Apartment | AI24: Prime | AJ24: TopTier | AK24: Prime resilient / selective | AL24: Better support from quality, branding, and scarcer prime stock; still entry-price sensitive. | AM24: 10.5 | AN24: 5.75 | AO24: 0.55 | AP24: 0.02 | AQ24: 0 | AR24: 0 | AS24: 0.03 | AT24: 0.005 | AU24: 0 | AV24: -0.005 | AW24: =IF(X24="","",(AM24/100*AO24)+AP24+AQ24+AR24) | AX24: =IF(X24="","",AS24+AT24+AU24+AV24) | AY24: =IF(AZ24="","",ROUND(AZ24*(1+Assumptions!$B$10),0)) | AZ24: =IF(X24="","",ROUND(X24*(1+AW24),0)) | BA24: =IF(AZ24="","",ROUND(AZ24*(1+Assumptions!$B$11),0)) | BB24: =IF(AZ24="","",ROUND(AZ24*(1+AX24+Assumptions!$B$10),0)) | BC24: =IF(AZ24="","",ROUND(AZ24*(1+AX24),0)) | BD24: =IF(AZ24="","",ROUND(AZ24*(1+AX24+Assumptions!$B$11),0)) | BE24: =IF(AZ24="","",ROUND(AZ24*(1+AX24)*(1+AX24),0)) | BF24: Rules-based enrichment using launch-price anchor, cap-app realization, and 2026 segment conditions. | BG24: 2026-03-17 | BH24: DLD / Digital Dubai / CBUAE / Savills / Knight Frank-Moody’s / Reuters
A25: 24 | B25: Montiva | C25: Emaar Properties | D25: Dubai Creek Harbour | E25: Apartments | F25: Waterfront | G25: 1.8M | H25: 2200 | I25: 25 | J25: 80/20 | K25: 2024 | L25: 5.5-6.0 | M25: 9-12 | N25: 14.5-18.0 | O25: Swiss Intl School | P25: American Hospital | Q25: Dubai Festival City | R25: Ras Al Khor / E44 | S25: 12 | T25: 25 | U25: 10 | V25: 40 | W25: 2 | X25: 1800000 | Y25: 1800000 | Z25: 5.5 | AA25: 6 | AB25: 9 | AC25: 12 | AD25: 14.5 | AE25: 18 | AF25: 2024 | AH25: Apartment | AI25: Prime | AJ25: TopTier | AK25: Prime resilient / selective | AL25: Better support from quality, branding, and scarcer prime stock; still entry-price sensitive. | AM25: 10.5 | AN25: 5.75 | AO25: 0.55 | AP25: 0.02 | AQ25: 0 | AR25: 0 | AS25: 0.03 | AT25: 0.005 | AU25: 0 | AV25: -0.005 | AW25: =IF(X25="","",(AM25/100*AO25)+AP25+AQ25+AR25) | AX25: =IF(X25="","",AS25+AT25+AU25+AV25) | AY25: =IF(AZ25="","",ROUND(AZ25*(1+Assumptions!$B$10),0)) | AZ25: =IF(X25="","",ROUND(X25*(1+AW25),0)) | BA25: =IF(AZ25="","",ROUND(AZ25*(1+Assumptions!$B$11),0)) | BB25: =IF(AZ25="","",ROUND(AZ25*(1+AX25+Assumptions!$B$10),0)) | BC25: =IF(AZ25="","",ROUND(AZ25*(1+AX25),0)) | BD25: =IF(AZ25="","",ROUND(AZ25*(1+AX25+Assumptions!$B$11),0)) | BE25: =IF(AZ25="","",ROUND(AZ25*(1+AX25)*(1+AX25),0)) | BF25: Rules-based enrichment using launch-price anchor, cap-app realization, and 2026 segment conditions. | BG25: 2026-03-17 | BH25: DLD / Digital Dubai / CBUAE / Savills / Knight Frank-Moody’s / Reuters
A26: 25 | B26: Creek Waters 1 | C26: Emaar Properties | D26: Dubai Creek Harbour | E26: Apartments | F26: Waterfront / Island | G26: 2.2M | H26: 2400 | I26: 25 | J26: 80/20 | K26: 2023 | L26: 5.0-5.5 | M26: 8-10 | N26: 13.0-15.5 | O26: Swiss Intl School | P26: American Hospital | Q26: Dubai Festival City | R26: Ras Al Khor / E44 | S26: 12 | T26: 25 | U26: 10 | V26: 40 | W26: 2 | X26: 2200000 | Y26: 2200000 | Z26: 5 | AA26: 5.5 | AB26: 8 | AC26: 10 | AD26: 13 | AE26: 15.5 | AF26: 2023 | AH26: Apartment | AI26: Prime | AJ26: TopTier | AK26: Prime resilient / selective | AL26: Better support from quality, branding, and scarcer prime stock; still entry-price sensitive. | AM26: 9 | AN26: 5.25 | AO26: 0.55 | AP26: 0.02 | AQ26: 0 | AR26: 0 | AS26: 0.03 | AT26: 0.005 | AU26: 0 | AV26: -0.005 | AW26: =IF(X26="","",(AM26/100*AO26)+AP26+AQ26+AR26) | AX26: =IF(X26="","",AS26+AT26+AU26+AV26) | AY26: =IF(AZ26="","",ROUND(AZ26*(1+Assumptions!$B$10),0)) | AZ26: =IF(X26="","",ROUND(X26*(1+AW26),0)) | BA26: =IF(AZ26="","",ROUND(AZ26*(1+Assumptions!$B$11),0)) | BB26: =IF(AZ26="","",ROUND(AZ26*(1+AX26+Assumptions!$B$10),0)) | BC26: =IF(AZ26="","",ROUND(AZ26*(1+AX26),0)) | BD26: =IF(AZ26="","",ROUND(AZ26*(1+AX26+Assumptions!$B$11),0)) | BE26: =IF(AZ26="","",ROUND(AZ26*(1+AX26)*(1+AX26),0)) | BF26: Rules-based enrichment using launch-price anchor, cap-app realization, and 2026 segment conditions. | BG26: 2026-03-17 | BH26: DLD / Digital Dubai / CBUAE / Savills / Knight Frank-Moody’s / Reuters
A27: 26 | B27: Creek Waters 2 | C27: Emaar Properties | D27: Dubai Creek Harbour | E27: Apartments | F27: Waterfront / Island | G27: 2.3M | H27: 2450 | I27: 25 | J27: 80/20 | K27: 2023 | L27: 5.0-5.5 | M27: 8-10 | N27: 13.0-15.5 | O27: Swiss Intl School | P27: American Hospital | Q27: Dubai Festival City | R27: Ras Al Khor / E44 | S27: 12 | T27: 25 | U27: 10 | V27: 40 | W27: 2 | X27: 2300000 | Y27: 2300000 | Z27: 5 | AA27: 5.5 | AB27: 8 | AC27: 10 | AD27: 13 | AE27: 15.5 | AF27: 2023 | AH27: Apartment | AI27: Prime | AJ27: TopTier | AK27: Prime resilient / selective | AL27: Better support from quality, branding, and scarcer prime stock; still entry-price sensitive. | AM27: 9 | AN27: 5.25 | AO27: 0.55 | AP27: 0.02 | AQ27: 0 | AR27: 0 | AS27: 0.03 | AT27: 0.005 | AU27: 0 | AV27: -0.005 | AW27: =IF(X27="","",(AM27/100*AO27)+AP27+AQ27+AR27) | AX27: =IF(X27="","",AS27+AT27+AU27+AV27) | AY27: =IF(AZ27="","",ROUND(AZ27*(1+Assumptions!$B$10),0)) | AZ27: =IF(X27="","",ROUND(X27*(1+AW27),0)) | BA27: =IF(AZ27="","",ROUND(AZ27*(1+Assumptions!$B$11),0)) | BB27: =IF(AZ27="","",ROUND(AZ27*(1+AX27+Assumptions!$B$10),0)) | BC27: =IF(AZ27="","",ROUND(AZ27*(1+AX27),0)) | BD27: =IF(AZ27="","",ROUND(AZ27*(1+AX27+Assumptions!$B$11),0)) | BE27: =IF(AZ27="","",ROUND(AZ27*(1+AX27)*(1+AX27),0)) | BF27: Rules-based enrichment using launch-price anchor, cap-app realization, and 2026 segment conditions. | BG27: 2026-03-17 | BH27: DLD / Digital Dubai / CBUAE / Savills / Knight Frank-Moody’s / Reuters
A28: 27 | B28: Creek Gate | C28: Emaar Properties | D28: Dubai Creek Harbour | E28: Apartments | F28: Waterfront | G28: Resale | H28: 1800 | I28: 25 | J28: Completed | K28: 2017 | L28: 6.0-6.5 | M28: 5-7 | N28: 11.0-13.5 | O28: Swiss Intl School | P28: American Hospital | Q28: Dubai Festival City | R28: Ras Al Khor / E44 | S28: 12 | T28: 25 | U28: 10 | V28: 40 | W28: 2 | Z28: 6 | AA28: 6.5 | AB28: 5 | AC28: 7 | AD28: 11 | AE28: 13.5 | AF28: 2017 | AH28: Apartment | AI28: Prime | AJ28: TopTier | AK28: Prime resilient / selective | AL28: Better support from quality, branding, and scarcer prime stock; still entry-price sensitive. | AM28: 6 | AN28: 6.25 | AO28: 0.55 | AP28: 0.02 | AQ28: 0 | AR28: 0 | AS28: 0.03 | AT28: 0.005 | AU28: 0.0025 | AV28: -0.005 | AW28: =IF(X28="","",(AM28/100*AO28)+AP28+AQ28+AR28) | AX28: =IF(X28="","",AS28+AT28+AU28+AV28) | AY28: =IF(AZ28="","",ROUND(AZ28*(1+Assumptions!$B$10),0)) | AZ28: =IF(X28="","",ROUND(X28*(1+AW28),0)) | BA28: =IF(AZ28="","",ROUND(AZ28*(1+Assumptions!$B$11),0)) | BB28: =IF(AZ28="","",ROUND(AZ28*(1+AX28+Assumptions!$B$10),0)) | BC28: =IF(AZ28="","",ROUND(AZ28*(1+AX28),0)) | BD28: =IF(AZ28="","",ROUND(AZ28*(1+AX28+Assumptions!$B$11),0)) | BE28: =IF(AZ28="","",ROUND(AZ28*(1+AX28)*(1+AX28),0)) | BF28: Rules-based enrichment using launch-price anchor, cap-app realization, and 2026 segment conditions. | BG28: 2026-03-17 | BH28: DLD / Digital Dubai / CBUAE / Savills / Knight Frank-Moody’s / Reuters
A29: 28 | B29: Address Grand Creek | C29: Emaar Properties | D29: Dubai Creek Harbour | E29: Branded Residences | F29: Luxury Hotel | G29: 3.5M | H29: 3500 | I29: 45+ | J29: Varies | K29: 2023 | L29: 4.0-5.0 | M29: 8-10 | N29: 12.0-15.0 | O29: Swiss Intl School | P29: American Hospital | Q29: Dubai Festival City | R29: Ras Al Khor / E44 | S29: 12 | T29: 25 | U29: 10 | V29: 40 | W29: 2 | X29: 3500000 | Y29: 3500000 | Z29: 4 | AA29: 5 | AB29: 8 | AC29: 10 | AD29: 12 | AE29: 15 | AF29: 2023 | AH29: Apartment | AI29: Prime | AJ29: TopTier | AK29: Prime resilient / selective | AL29: Better support from quality, branding, and scarcer prime stock; still entry-price sensitive. | AM29: 9 | AN29: 4.5 | AO29: 0.55 | AP29: 0.02 | AQ29: 0 | AR29: 0 | AS29: 0.03 | AT29: 0.005 | AU29: 0 | AV29: -0.005 | AW29: =IF(X29="","",(AM29/100*AO29)+AP29+AQ29+AR29) | AX29: =IF(X29="","",AS29+AT29+AU29+AV29) | AY29: =IF(AZ29="","",ROUND(AZ29*(1+Assumptions!$B$10),0)) | AZ29: =IF(X29="","",ROUND(X29*(1+AW29),0)) | BA29: =IF(AZ29="","",ROUND(AZ29*(1+Assumptions!$B$11),0)) | BB29: =IF(AZ29="","",ROUND(AZ29*(1+AX29+Assumptions!$B$10),0)) | BC29: =IF(AZ29="","",ROUND(AZ29*(1+AX29),0)) | BD29: =IF(AZ29="","",ROUND(AZ29*(1+AX29+Assumptions!$B$11),0)) | BE29: =IF(AZ29="","",ROUND(AZ29*(1+AX29)*(1+AX29),0)) | BF29: Rules-based enrichment using launch-price anchor, cap-app realization, and 2026 segment conditions. | BG29: 2026-03-17 | BH29: DLD / Digital Dubai / CBUAE / Savills / Knight Frank-Moody’s / Reuters
A30: 29 | B30: Dubai Hills Estate | C30: Emaar Properties | D30: Al Khail Road | E30: Mixed | F30: Golf / Central Park | I30: 20-25 | J30: Varies | K30: Ongoing | L30: 5.5-6.5 | M30: 8-12 | N30: 13.5-18.5 | O30: GEMS Wellington | P30: King's College Hospital | Q30: Dubai Hills Mall | R30: Al Khail E44 | S30: 15 | T30: 15 | U30: 20 | V30: 30 | W30: 2 | Z30: 5.5 | AA30: 6.5 | AB30: 8 | AC30: 12 | AD30: 13.5 | AE30: 18.5 | AH30: Mixed/Other | AI30: MainstreamSelective | AJ30: TopTier | AK30: Balanced / selective | AL30: Market remains active but increasingly differentiated by developer, micro-location, livability, and pricing discipline. | AM30: 10 | AN30: 6 | AO30: 0.25 | AP30: 0 | AQ30: 0 | AR30: 0 | AS30: 0.01 | AT30: 0.005 | AU30: 0 | AV30: -0.005 | AW30: =IF(X30="","",(AM30/100*AO30)+AP30+AQ30+AR30) | AX30: =IF(X30="","",AS30+AT30+AU30+AV30) | AY30: =IF(AZ30="","",ROUND(AZ30*(1+Assumptions!$B$10),0)) | AZ30: =IF(X30="","",ROUND(X30*(1+AW30),0)) | BA30: =IF(AZ30="","",ROUND(AZ30*(1+Assumptions!$B$11),0)) | BB30: =IF(AZ30="","",ROUND(AZ30*(1+AX30+Assumptions!$B$10),0)) | BC30: =IF(AZ30="","",ROUND(AZ30*(1+AX30),0)) | BD30: =IF(AZ30="","",ROUND(AZ30*(1+AX30+Assumptions!$B$11),0)) | BE30: =IF(AZ30="","",ROUND(AZ30*(1+AX30)*(1+AX30),0)) | BF30: Rules-based enrichment using launch-price anchor, cap-app realization, and 2026 segment conditions. | BG30: 2026-03-17 | BH30: DLD / Digital Dubai / CBUAE / Savills / Knight Frank-Moody’s / Reuters
A31: 30 | B31: Park Gate 2 | C31: Emaar Properties | D31: Dubai Hills Estate | E31: Villas | F31: Gated / Park | G31: 4.5M | H31: 1800 | I31: 20 | J31: 80/20 | K31: 2024 | L31: 5.0-5.5 | M31: 8-12 | N31: 13.0-17.5 | O31: GEMS Wellington | P31: King's College Hospital | Q31: Dubai Hills Mall | R31: Al Khail E44 | S31: 15 | T31: 15 | U31: 20 | V31: 30 | W31: 2 | X31: 4500000 | Y31: 4500000 | Z31: 5 | AA31: 5.5 | AB31: 8 | AC31: 12 | AD31: 13 | AE31: 17.5 | AF31: 2024 | AH31: Villa | AI31: Prime | AJ31: TopTier | AK31: Prime resilient / selective | AL31: Better support from quality, branding, and scarcer prime stock; still entry-price sensitive. | AM31: 10 | AN31: 5.25 | AO31: 0.55 | AP31: 0.02 | AQ31: 0.015 | AR31: 0 | AS31: 0.03 | AT31: 0.005 | AU31: 0 | AV31: -0.005 | AW31: =IF(X31="","",(AM31/100*AO31)+AP31+AQ31+AR31) | AX31: =IF(X31="","",AS31+AT31+AU31+AV31) | AY31: =IF(AZ31="","",ROUND(AZ31*(1+Assumptions!$B$10),0)) | AZ31: =IF(X31="","",ROUND(X31*(1+AW31),0)) | BA31: =IF(AZ31="","",ROUND(AZ31*(1+Assumptions!$B$11),0)) | BB31: =IF(AZ31="","",ROUND(AZ31*(1+AX31+Assumptions!$B$10),0)) | BC31: =IF(AZ31="","",ROUND(AZ31*(1+AX31),0)) | BD31: =IF(AZ31="","",ROUND(AZ31*(1+AX31+Assumptions!$B$11),0)) | BE31: =IF(AZ31="","",ROUND(AZ31*(1+AX31)*(1+AX31),0)) | BF31: Rules-based enrichment using launch-price anchor, cap-app realization, and 2026 segment conditions. | BG31: 2026-03-17 | BH31: DLD / Digital Dubai / CBUAE / Savills / Knight Frank-Moody’s / Reuters
A32: 31 | B32: Rosehill | C32: Emaar Properties | D32: Dubai Hills Estate | E32: Apartments | F32: Community View | G32: 1.6M | H32: 1900 | I32: 22 | J32: 80/20 | K32: 2024 | L32: 6.0-6.5 | M32: 8-12 | N32: 14.0-18.5 | O32: GEMS Wellington | P32: King's College Hospital | Q32: Dubai Hills Mall | R32: Al Khail E44 | S32: 15 | T32: 15 | U32: 20 | V32: 30 | W32: 2 | X32: 1600000 | Y32: 1600000 | Z32: 6 | AA32: 6.5 | AB32: 8 | AC32: 12 | AD32: 14 | AE32: 18.5 | AF32: 2024 | AH32: Apartment | AI32: Prime | AJ32: TopTier | AK32: Prime resilient / selective | AL32: Better support from quality, branding, and scarcer prime stock; still entry-price sensitive. | AM32: 10 | AN32: 6.25 | AO32: 0.55 | AP32: 0.02 | AQ32: 0 | AR32: 0 | AS32: 0.03 | AT32: 0.005 | AU32: 0.0025 | AV32: -0.005 | AW32: =IF(X32="","",(AM32/100*AO32)+AP32+AQ32+AR32) | AX32: =IF(X32="","",AS32+AT32+AU32+AV32) | AY32: =IF(AZ32="","",ROUND(AZ32*(1+Assumptions!$B$10),0)) | AZ32: =IF(X32="","",ROUND(X32*(1+AW32),0)) | BA32: =IF(AZ32="","",ROUND(AZ32*(1+Assumptions!$B$11),0)) | BB32: =IF(AZ32="","",ROUND(AZ32*(1+AX32+Assumptions!$B$10),0)) | BC32: =IF(AZ32="","",ROUND(AZ32*(1+AX32),0)) | BD32: =IF(AZ32="","",ROUND(AZ32*(1+AX32+Assumptions!$B$11),0)) | BE32: =IF(AZ32="","",ROUND(AZ32*(1+AX32)*(1+AX32),0)) | BF32: Rules-based enrichment using launch-price anchor, cap-app realization, and 2026 segment conditions. | BG32: 2026-03-17 | BH32: DLD / Digital Dubai / CBUAE / Savills / Knight Frank-Moody’s / Reuters
A33: 32 | B33: Greencrest | C33: Emaar Properties | D33: Dubai Hills Estate | E33: Apartments | F33: Community View | G33: 1.55M | H33: 1850 | I33: 22 | J33: 80/20 | K33: 2024 | L33: 6.0-6.5 | M33: 8-12 | N33: 14.0-18.5 | O33: GEMS Wellington | P33: King's College Hospital | Q33: Dubai Hills Mall | R33: Al Khail E44 | S33: 15 | T33: 15 | U33: 20 | V33: 30 | W33: 2 | X33: 1550000 | Y33: 1550000 | Z33: 6 | AA33: 6.5 | AB33: 8 | AC33: 12 | AD33: 14 | AE33: 18.5 | AF33: 2024 | AH33: Apartment | AI33: Prime | AJ33: TopTier | AK33: Prime resilient / selective | AL33: Better support from quality, branding, and scarcer prime stock; still entry-price sensitive. | AM33: 10 | AN33: 6.25 | AO33: 0.55 | AP33: 0.02 | AQ33: 0 | AR33: 0 | AS33: 0.03 | AT33: 0.005 | AU33: 0.0025 | AV33: -0.005 | AW33: =IF(X33="","",(AM33/100*AO33)+AP33+AQ33+AR33) | AX33: =IF(X33="","",AS33+AT33+AU33+AV33) | AY33: =IF(AZ33="","",ROUND(AZ33*(1+Assumptions!$B$10),0)) | AZ33: =IF(X33="","",ROUND(X33*(1+AW33),0)) | BA33: =IF(AZ33="","",ROUND(AZ33*(1+Assumptions!$B$11),0)) | BB33: =IF(AZ33="","",ROUND(AZ33*(1+AX33+Assumptions!$B$10),0)) | BC33: =IF(AZ33="","",ROUND(AZ33*(1+AX33),0)) | BD33: =IF(AZ33="","",ROUND(AZ33*(1+AX33+Assumptions!$B$11),0)) | BE33: =IF(AZ33="","",ROUND(AZ33*(1+AX33)*(1+AX33),0)) | BF33: Rules-based enrichment using launch-price anchor, cap-app realization, and 2026 segment conditions. | BG33: 2026-03-17 | BH33: DLD / Digital Dubai / CBUAE / Savills / Knight Frank-Moody’s / Reuters
A34: 33 | B34: Palace Residences Hillside | C34: Emaar Properties | D34: Dubai Hills Estate | E34: Branded Apartments | F34: Golf / Park | G34: 2.5M | H34: 2400 | I34: 35 | J34: 80/20 | K34: 2024 | L34: 4.5-5.0 | M34: 8-12 | N34: 12.5-17.0 | O34: GEMS Wellington | P34: King's College Hospital | Q34: Dubai Hills Mall | R34: Al Khail E44 | S34: 15 | T34: 15 | U34: 20 | V34: 30 | W34: 2 | X34: 2500000 | Y34: 2500000 | Z34: 4.5 | AA34: 5 | AB34: 8 | AC34: 12 | AD34: 12.5 | AE34: 17 | AF34: 2024 | AH34: Apartment | AI34: Prime | AJ34: TopTier | AK34: Prime resilient / selective | AL34: Better support from quality, branding, and scarcer prime stock; still entry-price sensitive. | AM34: 10 | AN34: 4.75 | AO34: 0.55 | AP34: 0.02 | AQ34: 0 | AR34: 0 | AS34: 0.03 | AT34: 0.005 | AU34: 0 | AV34: -0.005 | AW34: =IF(X34="","",(AM34/100*AO34)+AP34+AQ34+AR34) | AX34: =IF(X34="","",AS34+AT34+AU34+AV34) | AY34: =IF(AZ34="","",ROUND(AZ34*(1+Assumptions!$B$10),0)) | AZ34: =IF(X34="","",ROUND(X34*(1+AW34),0)) | BA34: =IF(AZ34="","",ROUND(AZ34*(1+Assumptions!$B$11),0)) | BB34: =IF(AZ34="","",ROUND(AZ34*(1+AX34+Assumptions!$B$10),0)) | BC34: =IF(AZ34="","",ROUND(AZ34*(1+AX34),0)) | BD34: =IF(AZ34="","",ROUND(AZ34*(1+AX34+Assumptions!$B$11),0)) | BE34: =IF(AZ34="","",ROUND(AZ34*(1+AX34)*(1+AX34),0)) | BF34: Rules-based enrichment using launch-price anchor, cap-app realization, and 2026 segment conditions. | BG34: 2026-03-17 | BH34: DLD / Digital Dubai / CBUAE / Savills / Knight Frank-Moody’s / Reuters
A35: 34 | B35: Vida Residences Hillside | C35: Emaar Properties | D35: Dubai Hills Estate | E35: Branded Apartments | F35: Golf / Park | G35: 2.2M | H35: 2200 | I35: 30 | J35: 80/20 | K35: 2024 | L35: 5.0-5.5 | M35: 8-12 | N35: 13.0-17.5 | O35: GEMS Wellington | P35: King's College Hospital | Q35: Dubai Hills Mall | R35: Al Khail E44 | S35: 15 | T35: 15 | U35: 20 | V35: 30 | W35: 2 | X35: 2200000 | Y35: 2200000 | Z35: 5 | AA35: 5.5 | AB35: 8 | AC35: 12 | AD35: 13 | AE35: 17.5 | AF35: 2024 | AH35: Apartment | AI35: Prime | AJ35: TopTier | AK35: Prime resilient / selective | AL35: Better support from quality, branding, and scarcer prime stock; still entry-price sensitive. | AM35: 10 | AN35: 5.25 | AO35: 0.55 | AP35: 0.02 | AQ35: 0 | AR35: 0 | AS35: 0.03 | AT35: 0.005 | AU35: 0 | AV35: -0.005 | AW35: =IF(X35="","",(AM35/100*AO35)+AP35+AQ35+AR35) | AX35: =IF(X35="","",AS35+AT35+AU35+AV35) | AY35: =IF(AZ35="","",ROUND(AZ35*(1+Assumptions!$B$10),0)) | AZ35: =IF(X35="","",ROUND(X35*(1+AW35),0)) | BA35: =IF(AZ35="","",ROUND(AZ35*(1+Assumptions!$B$11),0)) | BB35: =IF(AZ35="","",ROUND(AZ35*(1+AX35+Assumptions!$B$10),0)) | BC35: =IF(AZ35="","",ROUND(AZ35*(1+AX35),0)) | BD35: =IF(AZ35="","",ROUND(AZ35*(1+AX35+Assumptions!$B$11),0)) | BE35: =IF(AZ35="","",ROUND(AZ35*(1+AX35)*(1+AX35),0)) | BF35: Rules-based enrichment using launch-price anchor, cap-app realization, and 2026 segment conditions. | BG35: 2026-03-17 | BH35: DLD / Digital Dubai / CBUAE / Savills / Knight Frank-Moody’s / Reuters
A36: 35 | B36: Golf Hillside | C36: Emaar Properties | D36: Dubai Hills Estate | E36: Apartments | F36: Golf Course | G36: 1.8M | H36: 2000 | I36: 22 | J36: 80/20 | K36: 2024 | L36: 5.5-6.0 | M36: 8-12 | N36: 13.5-18.0 | O36: GEMS Wellington | P36: King's College Hospital | Q36: Dubai Hills Mall | R36: Al Khail E44 | S36: 15 | T36: 15 | U36: 20 | V36: 30 | W36: 2 | X36: 1800000 | Y36: 1800000 | Z36: 5.5 | AA36: 6 | AB36: 8 | AC36: 12 | AD36: 13.5 | AE36: 18 | AF36: 2024 | AH36: Apartment | AI36: Prime | AJ36: TopTier | AK36: Prime resilient / selective | AL36: Better support from quality, branding, and scarcer prime stock; still entry-price sensitive. | AM36: 10 | AN36: 5.75 | AO36: 0.55 | AP36: 0.02 | AQ36: 0 | AR36: 0 | AS36: 0.03 | AT36: 0.005 | AU36: 0 | AV36: -0.005 | AW36: =IF(X36="","",(AM36/100*AO36)+AP36+AQ36+AR36) | AX36: =IF(X36="","",AS36+AT36+AU36+AV36) | AY36: =IF(AZ36="","",ROUND(AZ36*(1+Assumptions!$B$10),0)) | AZ36: =IF(X36="","",ROUND(X36*(1+AW36),0)) | BA36: =IF(AZ36="","",ROUND(AZ36*(1+Assumptions!$B$11),0)) | BB36: =IF(AZ36="","",ROUND(AZ36*(1+AX36+Assumptions!$B$10),0)) | BC36: =IF(AZ36="","",ROUND(AZ36*(1+AX36),0)) | BD36: =IF(AZ36="","",ROUND(AZ36*(1+AX36+Assumptions!$B$11),0)) | BE36: =IF(AZ36="","",ROUND(AZ36*(1+AX36)*(1+AX36),0)) | BF36: Rules-based enrichment using launch-price anchor, cap-app realization, and 2026 segment conditions. | BG36: 2026-03-17 | BH36: DLD / Digital Dubai / CBUAE / Savills / Knight Frank-Moody’s / Reuters
A37: 36 | B37: Parkland | C37: Emaar Properties | D37: Dubai Hills Estate | E37: Apartments | F37: Park View | G37: 1.7M | H37: 1950 | I37: 22 | J37: 80/20 | K37: 2024 | L37: 5.5-6.0 | M37: 8-12 | N37: 13.5-18.0 | O37: GEMS Wellington | P37: King's College Hospital | Q37: Dubai Hills Mall | R37: Al Khail E44 | S37: 15 | T37: 15 | U37: 20 | V37: 30 | W37: 2 | X37: 1700000 | Y37: 1700000 | Z37: 5.5 | AA37: 6 | AB37: 8 | AC37: 12 | AD37: 13.5 | AE37: 18 | AF37: 2024 | AH37: Apartment | AI37: Prime | AJ37: TopTier | AK37: Prime resilient / selective | AL37: Better support from quality, branding, and scarcer prime stock; still entry-price sensitive. | AM37: 10 | AN37: 5.75 | AO37: 0.55 | AP37: 0.02 | AQ37: 0 | AR37: 0 | AS37: 0.03 | AT37: 0.005 | AU37: 0 | AV37: -0.005 | AW37: =IF(X37="","",(AM37/100*AO37)+AP37+AQ37+AR37) | AX37: =IF(X37="","",AS37+AT37+AU37+AV37) | AY37: =IF(AZ37="","",ROUND(AZ37*(1+Assumptions!$B$10),0)) | AZ37: =IF(X37="","",ROUND(X37*(1+AW37),0)) | BA37: =IF(AZ37="","",ROUND(AZ37*(1+Assumptions!$B$11),0)) | BB37: =IF(AZ37="","",ROUND(AZ37*(1+AX37+Assumptions!$B$10),0)) | BC37: =IF(AZ37="","",ROUND(AZ37*(1+AX37),0)) | BD37: =IF(AZ37="","",ROUND(AZ37*(1+AX37+Assumptions!$B$11),0)) | BE37: =IF(AZ37="","",ROUND(AZ37*(1+AX37)*(1+AX37),0)) | BF37: Rules-based enrichment using launch-price anchor, cap-app realization, and 2026 segment conditions. | BG37: 2026-03-17 | BH37: DLD / Digital Dubai / CBUAE / Savills / Knight Frank-Moody’s / Reuters
A38: 37 | B38: Sidra Villas | C38: Emaar Properties | D38: Dubai Hills Estate | E38: Villas | F38: Gated Community | G38: Resale (5M+) | H38: 1600 | I38: 15 | J38: Completed | K38: 2016 | L38: 5.5-6.0 | M38: 6-8 | N38: 11.5-14.0 | O38: GEMS Wellington | P38: King's College Hospital | Q38: Dubai Hills Mall | R38: Al Khail E44 | S38: 15 | T38: 15 | U38: 20 | V38: 30 | W38: 2 | X38: 5000000 | Y38: 5000000 | Z38: 5.5 | AA38: 6 | AB38: 6 | AC38: 8 | AD38: 11.5 | AE38: 14 | AF38: 2016 | AH38: Villa | AI38: Prime | AJ38: TopTier | AK38: Prime resilient / selective | AL38: Better support from quality, branding, and scarcer prime stock; still entry-price sensitive. | AM38: 7 | AN38: 5.75 | AO38: 0.55 | AP38: 0.02 | AQ38: 0.015 | AR38: 0 | AS38: 0.03 | AT38: 0.005 | AU38: 0 | AV38: -0.005 | AW38: =IF(X38="","",(AM38/100*AO38)+AP38+AQ38+AR38) | AX38: =IF(X38="","",AS38+AT38+AU38+AV38) | AY38: =IF(AZ38="","",ROUND(AZ38*(1+Assumptions!$B$10),0)) | AZ38: =IF(X38="","",ROUND(X38*(1+AW38),0)) | BA38: =IF(AZ38="","",ROUND(AZ38*(1+Assumptions!$B$11),0)) | BB38: =IF(AZ38="","",ROUND(AZ38*(1+AX38+Assumptions!$B$10),0)) | BC38: =IF(AZ38="","",ROUND(AZ38*(1+AX38),0)) | BD38: =IF(AZ38="","",ROUND(AZ38*(1+AX38+Assumptions!$B$11),0)) | BE38: =IF(AZ38="","",ROUND(AZ38*(1+AX38)*(1+AX38),0)) | BF38: Rules-based enrichment using launch-price anchor, cap-app realization, and 2026 segment conditions. | BG38: 2026-03-17 | BH38: DLD / Digital Dubai / CBUAE / Savills / Knight Frank-Moody’s / Reuters
A39: 38 | B39: Maple Townhouses | C39: Emaar Properties | D39: Dubai Hills Estate | E39: Townhouses | F39: Gated Community | G39: Resale (3.5M+) | H39: 1500 | I39: 15 | J39: Completed | K39: 2016 | L39: 6.0-6.5 | M39: 6-8 | N39: 12.0-14.5 | O39: GEMS Wellington | P39: King's College Hospital | Q39: Dubai Hills Mall | R39: Al Khail E44 | S39: 15 | T39: 15 | U39: 20 | V39: 30 | W39: 2 | X39: 3500000 | Y39: 3500000 | Z39: 6 | AA39: 6.5 | AB39: 6 | AC39: 8 | AD39: 12 | AE39: 14.5 | AF39: 2016 | AH39: Townhouse | AI39: Prime | AJ39: TopTier | AK39: Prime resilient / selective | AL39: Better support from quality, branding, and scarcer prime stock; still entry-price sensitive. | AM39: 7 | AN39: 6.25 | AO39: 0.55 | AP39: 0.02 | AQ39: 0.015 | AR39: 0 | AS39: 0.03 | AT39: 0.005 | AU39: 0.0025 | AV39: -0.005 | AW39: =IF(X39="","",(AM39/100*AO39)+AP39+AQ39+AR39) | AX39: =IF(X39="","",AS39+AT39+AU39+AV39) | AY39: =IF(AZ39="","",ROUND(AZ39*(1+Assumptions!$B$10),0)) | AZ39: =IF(X39="","",ROUND(X39*(1+AW39),0)) | BA39: =IF(AZ39="","",ROUND(AZ39*(1+Assumptions!$B$11),0)) | BB39: =IF(AZ39="","",ROUND(AZ39*(1+AX39+Assumptions!$B$10),0)) | BC39: =IF(AZ39="","",ROUND(AZ39*(1+AX39),0)) | BD39: =IF(AZ39="","",ROUND(AZ39*(1+AX39+Assumptions!$B$11),0)) | BE39: =IF(AZ39="","",ROUND(AZ39*(1+AX39)*(1+AX39),0)) | BF39: Rules-based enrichment using launch-price anchor, cap-app realization, and 2026 segment conditions. | BG39: 2026-03-17 | BH39: DLD / Digital Dubai / CBUAE / Savills / Knight Frank-Moody’s / Reuters
A40: 39 | B40: Address Villas Hillcrest | C40: Emaar Properties | D40: Dubai Hills Estate | E40: Villas | F40: Luxury / Golf | G40: 8.0M | H40: 2200 | I40: 25 | J40: 80/20 | K40: 2023 | L40: 4.5-5.0 | M40: 8-10 | N40: 12.5-15.0 | O40: GEMS Wellington | P40: King's College Hospital | Q40: Dubai Hills Mall | R40: Al Khail E44 | S40: 15 | T40: 15 | U40: 20 | V40: 30 | W40: 2 | X40: 8000000 | Y40: 8000000 | Z40: 4.5 | AA40: 5 | AB40: 8 | AC40: 10 | AD40: 12.5 | AE40: 15 | AF40: 2023 | AH40: Villa | AI40: Prime | AJ40: TopTier | AK40: Prime resilient / selective | AL40: Better support from quality, branding, and scarcer prime stock; still entry-price sensitive. | AM40: 9 | AN40: 4.75 | AO40: 0.55 | AP40: 0.02 | AQ40: 0.015 | AR40: 0 | AS40: 0.03 | AT40: 0.005 | AU40: 0 | AV40: -0.005 | AW40: =IF(X40="","",(AM40/100*AO40)+AP40+AQ40+AR40) | AX40: =IF(X40="","",AS40+AT40+AU40+AV40) | AY40: =IF(AZ40="","",ROUND(AZ40*(1+Assumptions!$B$10),0)) | AZ40: =IF(X40="","",ROUND(X40*(1+AW40),0)) | BA40: =IF(AZ40="","",ROUND(AZ40*(1+Assumptions!$B$11),0)) | BB40: =IF(AZ40="","",ROUND(AZ40*(1+AX40+Assumptions!$B$10),0)) | BC40: =IF(AZ40="","",ROUND(AZ40*(1+AX40),0)) | BD40: =IF(AZ40="","",ROUND(AZ40*(1+AX40+Assumptions!$B$11),0)) | BE40: =IF(AZ40="","",ROUND(AZ40*(1+AX40)*(1+AX40),0)) | BF40: Rules-based enrichment using launch-price anchor, cap-app realization, and 2026 segment conditions. | BG40: 2026-03-17 | BH40: DLD / Digital Dubai / CBUAE / Savills / Knight Frank-Moody’s / Reuters
...

Sheet Master_Values_Frozen
